{
    "registryname": "pressure_poop_injector",
    "localizedname": "Pressure Poop Injector",
    "parts": [
        {
            "x": -1,
            "y": 0,
            "z": 1,
            "nbt": {"casingColor":"5082769","ForgeCaps":{"nuclearcraft:capability_default_radiation_resistance":{"radiationResistance":"0.0d"}},"id":"minecraft:tilecolorablemachinecomponent"},
            "elements": [
                "modularmachinery:blockcasing@4"
            ]
        },
        {
            "x": -1,
            "y": 0,
            "z": 0,
            "nbt": {"busSize":"0","casingColor":"5082769","ForgeCaps":{"nuclearcraft:capability_default_radiation_resistance":{"radiationResistance":"0.0d"}},"id":"minecraft:tileitemoutputbus","inventory":{"inventoryArray":[{"holderEmpty":"1b","holderId":"0"}],"outSlots":,"miscSlots":,"inSlots":,"sides":}},
            "elements": [
                "modularmachinery:blockoutputbus@0"
            ]
        },
        {
            "x": 0,
            "y": 2,
            "z": 2,
            "elements": [
                "thermalfoundation:glass@3"
            ]
        },
        {
            "x": 1,
            "y": 2,
            "z": 1,
            "elements": [
                "immersiveengineering:sheetmetal@8"
            ]
        },
        {
            "x": 0,
            "y": 0,
            "z": 1,
            "nbt": {"casingColor":"5082769","ForgeCaps":{"nuclearcraft:capability_default_radiation_resistance":{"radiationResistance":"0.0d"}},"id":"minecraft:tilecolorablemachinecomponent"},
            "elements": [
                "modularmachinery:blockcasing@4"
            ]
        },
        {
            "x": 1,
            "y": 0,
            "z": 0,
            "nbt": {"hatchSize":"1","casingColor":"5082769","ForgeCaps":{"nuclearcraft:capability_default_radiation_resistance":{"radiationResistance":"0.0d"}},"id":"minecraft:tileenergyinputhatch","energy":"0L"},
            "elements": [
                "modularmachinery:blockenergyinputhatch@1"
            ]
        },
        {
            "x": -1,
            "y": 0,
            "z": 2,
            "nbt": {"casingColor":"5082769","ForgeCaps":{"nuclearcraft:capability_default_radiation_resistance":{"radiationResistance":"0.0d"}},"id":"minecraft:tilecolorablemachinecomponent"},
            "elements": [
                "modularmachinery:blockcasing@4"
            ]
        },
        {
            "x": 2,
            "y": 2,
            "z": 1,
            "nbt": {"TransferCooldown":"0","ForgeCaps":{"nuclearcraft:capability_default_radiation_resistance":{"radiationResistance":"0.0d"}},"Items":[],"id":"minecraft:tile.uppers.upper","Lock":""},
            "elements": [
                "uppers:upper@4"
            ]
        },
        {
            "x": 1,
            "y": 2,
            "z": 2,
            "elements": [
                "thermalfoundation:glass@3"
            ]
        },
        {
            "x": 0,
            "y": 0,
            "z": 2,
            "nbt": {"casingColor":"5082769","ForgeCaps":{"nuclearcraft:capability_default_radiation_resistance":{"radiationResistance":"0.0d"}},"id":"minecraft:tilecolorablemachinecomponent"},
            "elements": [
                "modularmachinery:blockcasing@4"
            ]
        },
        {
            "x": 1,
            "y": 0,
            "z": 1,
            "nbt": {"casingColor":"5082769","ForgeCaps":{"nuclearcraft:capability_default_radiation_resistance":{"radiationResistance":"0.0d"}},"id":"minecraft:tilecolorablemachinecomponent"},
            "elements": [
                "modularmachinery:blockcasing@4"
            ]
        },
        {
            "x": 1,
            "y": 0,
            "z": 2,
            "nbt": {"casingColor":"5082769","ForgeCaps":{"nuclearcraft:capability_default_radiation_resistance":{"radiationResistance":"0.0d"}},"id":"minecraft:tilecolorablemachinecomponent"},
            "elements": [
                "modularmachinery:blockcasing@4"
            ]
        },
        {
            "x": 2,
            "y": 0,
            "z": 1,
            "nbt": {"busSize":"0","casingColor":"5082769","ForgeCaps":{"nuclearcraft:capability_default_radiation_resistance":{"radiationResistance":"0.0d"}},"id":"minecraft:tileiteminputbus","inventory":{"inventoryArray":[{"holderEmpty":"1b","holderId":"0"}],"outSlots":,"miscSlots":,"inSlots":,"sides":}},
            "elements": [
                "modularmachinery:blockinputbus@0"
            ]
        },
        {
            "x": -2,
            "y": 3,
            "z": 1,
            "nbt": {"sideConfig":,"ForgeCaps":{"nuclearcraft:capability_default_radiation_resistance":{"radiationResistance":"0.0d"}},"id":"immersiveengineering:fluidpipe","connections":"3b"},
            "elements": [
                "immersiveengineering:metal_device1@6"
            ]
        },
        {
            "x": -1,
            "y": 3,
            "z": 0,
            "nbt": {"ForgeCaps":{"nuclearcraft:capability_default_radiation_resistance":{"radiationResistance":"0.0d"}},"id":"immersiveengineering:ieslab","slabType":"0"},
            "elements": [
                "immersiveengineering:sheetmetal_slab@9"
            ]
        },
        {
            "x": -1,
            "y": 3,
            "z": 1,
            "nbt": {"ForgeCaps":{"nuclearcraft:capability_default_radiation_resistance":{"radiationResistance":"0.0d"}},"id":"immersiveengineering:ieslab","slabType":"0"},
            "elements": [
                "immersiveengineering:sheetmetal_slab@9"
            ]
        },
        {
            "x": 0,
            "y": 3,
            "z": 0,
            "nbt": {"ForgeCaps":{"nuclearcraft:capability_default_radiation_resistance":{"radiationResistance":"0.0d"}},"id":"immersiveengineering:ieslab","slabType":"0"},
            "elements": [
                "immersiveengineering:sheetmetal_slab@9"
            ]
        },
        {
            "x": -2,
            "y": 1,
            "z": 1,
            "nbt": {"sideConfig":,"ForgeCaps":{"nuclearcraft:capability_default_radiation_resistance":{"radiationResistance":"0.0d"}},"id":"immersiveengineering:fluidpipe","connections":"3b"},
            "elements": [
                "immersiveengineering:metal_device1@6"
            ]
        },
        {
            "x": 0,
            "y": 3,
            "z": 1,
            "nbt": {"sideConfig":,"ForgeCaps":{"nuclearcraft:capability_default_radiation_resistance":{"radiationResistance":"0.0d"}},"id":"immersiveengineering:metalbarrel","tank":{"Empty":""}},
            "elements": [
                "immersiveengineering:metal_device0@4"
            ]
        },
        {
            "x": 1,
            "y": 3,
            "z": 0,
            "nbt": {"ForgeCaps":{"nuclearcraft:capability_default_radiation_resistance":{"radiationResistance":"0.0d"}},"id":"immersiveengineering:ieslab","slabType":"0"},
            "elements": [
                "immersiveengineering:sheetmetal_slab@9"
            ]
        },
        {
            "x": -1,
            "y": 3,
            "z": 2,
            "nbt": {"ForgeCaps":{"nuclearcraft:capability_default_radiation_resistance":{"radiationResistance":"0.0d"}},"id":"immersiveengineering:ieslab","slabType":"0"},
            "elements": [
                "immersiveengineering:sheetmetal_slab@9"
            ]
        },
        {
            "x": -1,
            "y": 1,
            "z": 0,
            "elements": [
                "immersiveengineering:sheetmetal@9"
            ]
        },
        {
            "x": 1,
            "y": 3,
            "z": 1,
            "nbt": {"ForgeCaps":{"nuclearcraft:capability_default_radiation_resistance":{"radiationResistance":"0.0d"}},"id":"immersiveengineering:ieslab","slabType":"0"},
            "elements": [
                "immersiveengineering:sheetmetal_slab@9"
            ]
        },
        {
            "x": 0,
            "y": 3,
            "z": 2,
            "nbt": {"ForgeCaps":{"nuclearcraft:capability_default_radiation_resistance":{"radiationResistance":"0.0d"}},"id":"immersiveengineering:ieslab","slabType":"0"},
            "elements": [
                "immersiveengineering:sheetmetal_slab@9"
            ]
        },
        {
            "x": -1,
            "y": 1,
            "z": 1,
            "elements": [
                "immersiveengineering:sheetmetal@9"
            ]
        },
        {
            "x": 0,
            "y": 1,
            "z": 0,
            "elements": [
                "immersiveengineering:sheetmetal@9"
            ]
        },
        {
            "x": 1,
            "y": 3,
            "z": 2,
            "nbt": {"ForgeCaps":{"nuclearcraft:capability_default_radiation_resistance":{"radiationResistance":"0.0d"}},"id":"immersiveengineering:ieslab","slabType":"0"},
            "elements": [
                "immersiveengineering:sheetmetal_slab@9"
            ]
        },
        {
            "x": -1,
            "y": 1,
            "z": 2,
            "elements": [
                "immersiveengineering:sheetmetal@9"
            ]
        },
        {
            "x": 0,
            "y": 1,
            "z": 1,
            "elements": [
                "immersiveengineering:sheetmetal@9"
            ]
        },
        {
            "x": 1,
            "y": 1,
            "z": 0,
            "elements": [
                "immersiveengineering:sheetmetal@9"
            ]
        },
        {
            "x": 0,
            "y": 1,
            "z": 2,
            "elements": [
                "immersiveengineering:sheetmetal@9"
            ]
        },
        {
            "x": 1,
            "y": 1,
            "z": 1,
            "elements": [
                "immersiveengineering:sheetmetal@9"
            ]
        },
        {
            "x": 2,
            "y": 1,
            "z": 1,
            "nbt": {"TransferCooldown":"0","ForgeCaps":{"nuclearcraft:capability_default_radiation_resistance":{"radiationResistance":"0.0d"}},"Items":[],"id":"minecraft:hopper","Lock":""},
            "elements": [
                "minecraft:hopper@0"
            ]
        },
        {
            "x": 1,
            "y": 1,
            "z": 2,
            "elements": [
                "immersiveengineering:sheetmetal@9"
            ]
        },
        {
            "x": -2,
            "y": 4,
            "z": 1,
            "nbt": {"sideConfig":,"ForgeCaps":{"nuclearcraft:capability_default_radiation_resistance":{"radiationResistance":"0.0d"}},"id":"immersiveengineering:fluidpipe","connections":"33b"},
            "elements": [
                "immersiveengineering:metal_device1@6"
            ]
        },
        {
            "x": -1,
            "y": 4,
            "z": 1,
            "nbt": {"sideConfig":,"ForgeCaps":{"nuclearcraft:capability_default_radiation_resistance":{"radiationResistance":"0.0d"}},"id":"immersiveengineering:fluidpipe","connections":"48b"},
            "elements": [
                "immersiveengineering:metal_device1@6"
            ]
        },
        {
            "x": -2,
            "y": 2,
            "z": 1,
            "nbt": {"sideConfig":,"ForgeCaps":{"nuclearcraft:capability_default_radiation_resistance":{"radiationResistance":"0.0d"}},"id":"immersiveengineering:fluidpipe","connections":"3b"},
            "elements": [
                "immersiveengineering:metal_device1@6"
            ]
        },
        {
            "x": 0,
            "y": 4,
            "z": 1,
            "nbt": {"sideConfig":,"ForgeCaps":{"nuclearcraft:capability_default_radiation_resistance":{"radiationResistance":"0.0d"}},"id":"immersiveengineering:fluidpipe","connections":"17b"},
            "elements": [
                "immersiveengineering:metal_device1@6"
            ]
        },
        {
            "x": -1,
            "y": 2,
            "z": 0,
            "elements": [
                "thermalfoundation:glass@3"
            ]
        },
        {
            "x": -1,
            "y": 2,
            "z": 1,
            "elements": [
                "thermalfoundation:glass@3"
            ]
        },
        {
            "x": 0,
            "y": 2,
            "z": 0,
            "elements": [
                "thermalfoundation:glass@3"
            ]
        },
        {
            "x": -2,
            "y": 0,
            "z": 1,
            "nbt": {"input":"1b","size":"1","casingColor":"5082769","ForgeCaps":{"nuclearcraft:capability_default_radiation_resistance":{"radiationResistance":"0.0d"}},"id":"minecraft:tilefluidinputhatch","tank":{"Empty":""}},
            "elements": [
                "modularmachinery:blockfluidinputhatch@1"
            ]
        },
        {
            "x": -1,
            "y": 2,
            "z": 2,
            "elements": [
                "thermalfoundation:glass@3"
            ]
        },
        {
            "x": 0,
            "y": 2,
            "z": 1,
            "elements": [
                "contenttweaker:glitched0@0"
            ]
        },
        {
            "x": 1,
            "y": 2,
            "z": 0,
            "elements": [
                "thermalfoundation:glass@3"
            ]
        }
    ]}